{"trial_id": "01", "hyperparameters": {"space": [{"class_name": "Int", "config": {"name": "num_layers", "default": null, "conditions": [], "min_value": 1, "max_value": 4, "step": 1, "sampling": "linear"}}, {"class_name": "Int", "config": {"name": "units_0", "default": null, "conditions": [], "min_value": 32, "max_value": 512, "step": 32, "sampling": "linear"}}, {"class_name": "Float", "config": {"name": "l2", "default": 1e-05, "conditions": [], "min_value": 1e-05, "max_value": 0.01, "step": null, "sampling": "log"}}, {"class_name": "Float", "config": {"name": "dropout_0", "default": 0.0, "conditions": [], "min_value": 0.0, "max_value": 0.5, "step": 0.1, "sampling": "linear"}}, {"class_name": "Float", "config": {"name": "learning_rate", "default": 0.0001, "conditions": [], "min_value": 0.0001, "max_value": 0.01, "step": null, "sampling": "log"}}], "values": {"num_layers": 1, "units_0": 224, "l2": 0.00011696078999495947, "dropout_0": 0.4, "learning_rate": 0.004827356183868775}}, "metrics": {"metrics": {}}, "score": null, "best_step": 0, "status": "FAILED", "message": "Traceback (most recent call last):\n  File \"/Users/karrtopelka/Developer/lnu/f1-v1/venv/lib/python3.12/site-packages/keras_tuner/src/engine/base_tuner.py\", line 274, in _try_run_and_update_trial\n    self._run_and_update_trial(trial, *fit_args, **fit_kwargs)\n  File \"/Users/karrtopelka/Developer/lnu/f1-v1/venv/lib/python3.12/site-packages/keras_tuner/src/engine/base_tuner.py\", line 239, in _run_and_update_trial\n    results = self.run_trial(trial, *fit_args, **fit_kwargs)\n              ^^^^^^^^^^^^^^^^^^^^^^^^^^^^^^^^^^^^^^^^^^^^^^\n  File \"/Users/karrtopelka/Developer/lnu/f1-v1/venv/lib/python3.12/site-packages/keras_tuner/src/engine/tuner.py\", line 314, in run_trial\n    obj_value = self._build_and_fit_model(trial, *args, **copied_kwargs)\n                ^^^^^^^^^^^^^^^^^^^^^^^^^^^^^^^^^^^^^^^^^^^^^^^^^^^^^^^^\n  File \"/Users/karrtopelka/Developer/lnu/f1-v1/venv/lib/python3.12/site-packages/keras_tuner/src/engine/tuner.py\", line 233, in _build_and_fit_model\n    results = self.hypermodel.fit(hp, model, *args, **kwargs)\n              ^^^^^^^^^^^^^^^^^^^^^^^^^^^^^^^^^^^^^^^^^^^^^^^\n  File \"/Users/karrtopelka/Developer/lnu/f1-v1/venv/lib/python3.12/site-packages/keras_tuner/src/engine/hypermodel.py\", line 149, in fit\n    return model.fit(*args, **kwargs)\n           ^^^^^^^^^^^^^^^^^^^^^^^^^^\n  File \"/Users/karrtopelka/Developer/lnu/f1-v1/venv/lib/python3.12/site-packages/keras/src/utils/traceback_utils.py\", line 122, in error_handler\n    raise e.with_traceback(filtered_tb) from None\n  File \"/Users/karrtopelka/Developer/lnu/f1-v1/venv/lib/python3.12/site-packages/keras/src/trainers/compile_utils.py\", line 539, in build\n    raise ValueError(\nValueError: For a model with multiple outputs, when providing the `loss` argument as a list, it should have as many entries as the model has outputs. Received:\nloss=[<function quantile_loss.<locals>.loss at 0x38092d620>, <function quantile_loss.<locals>.loss at 0x38092d760>]\nof length 2 whereas the model has 1 outputs.\n"}